{
 "cells": [
  {
   "cell_type": "code",
   "execution_count": 2,
   "id": "2b0adf10-d46e-4c52-9ae8-662b246b064c",
   "metadata": {},
   "outputs": [],
   "source": [
    "import pandas as pd\n",
    "import matplotlib.pyplot as plt\n",
    "import seaborn as sns\n",
    "import psycopg2\n",
    "\n",
    "%load_ext sql"
   ]
  },
  {
   "cell_type": "code",
   "execution_count": 3,
   "id": "f6a86db7-56ba-4413-b655-5973a6090db3",
   "metadata": {},
   "outputs": [
    {
     "name": "stdout",
     "output_type": "stream",
     "text": [
      "Traceback (most recent call last):\n",
      "  File \"/usr/local/python/3.12.1/lib/python3.12/site-packages/sqlalchemy/engine/base.py\", line 146, in __init__\n",
      "    self._dbapi_connection = engine.raw_connection()\n",
      "                             ^^^^^^^^^^^^^^^^^^^^^^^\n",
      "  File \"/usr/local/python/3.12.1/lib/python3.12/site-packages/sqlalchemy/engine/base.py\", line 3298, in raw_connection\n",
      "    return self.pool.connect()\n",
      "           ^^^^^^^^^^^^^^^^^^^\n",
      "  File \"/usr/local/python/3.12.1/lib/python3.12/site-packages/sqlalchemy/pool/base.py\", line 449, in connect\n",
      "    return _ConnectionFairy._checkout(self)\n",
      "           ^^^^^^^^^^^^^^^^^^^^^^^^^^^^^^^^\n",
      "  File \"/usr/local/python/3.12.1/lib/python3.12/site-packages/sqlalchemy/pool/base.py\", line 1263, in _checkout\n",
      "    fairy = _ConnectionRecord.checkout(pool)\n",
      "            ^^^^^^^^^^^^^^^^^^^^^^^^^^^^^^^^\n",
      "  File \"/usr/local/python/3.12.1/lib/python3.12/site-packages/sqlalchemy/pool/base.py\", line 712, in checkout\n",
      "    rec = pool._do_get()\n",
      "          ^^^^^^^^^^^^^^\n",
      "  File \"/usr/local/python/3.12.1/lib/python3.12/site-packages/sqlalchemy/pool/impl.py\", line 179, in _do_get\n",
      "    with util.safe_reraise():\n",
      "  File \"/usr/local/python/3.12.1/lib/python3.12/site-packages/sqlalchemy/util/langhelpers.py\", line 146, in __exit__\n",
      "    raise exc_value.with_traceback(exc_tb)\n",
      "  File \"/usr/local/python/3.12.1/lib/python3.12/site-packages/sqlalchemy/pool/impl.py\", line 177, in _do_get\n",
      "    return self._create_connection()\n",
      "           ^^^^^^^^^^^^^^^^^^^^^^^^^\n",
      "  File \"/usr/local/python/3.12.1/lib/python3.12/site-packages/sqlalchemy/pool/base.py\", line 390, in _create_connection\n",
      "    return _ConnectionRecord(self)\n",
      "           ^^^^^^^^^^^^^^^^^^^^^^^\n",
      "  File \"/usr/local/python/3.12.1/lib/python3.12/site-packages/sqlalchemy/pool/base.py\", line 674, in __init__\n",
      "    self.__connect()\n",
      "  File \"/usr/local/python/3.12.1/lib/python3.12/site-packages/sqlalchemy/pool/base.py\", line 900, in __connect\n",
      "    with util.safe_reraise():\n",
      "  File \"/usr/local/python/3.12.1/lib/python3.12/site-packages/sqlalchemy/util/langhelpers.py\", line 146, in __exit__\n",
      "    raise exc_value.with_traceback(exc_tb)\n",
      "  File \"/usr/local/python/3.12.1/lib/python3.12/site-packages/sqlalchemy/pool/base.py\", line 896, in __connect\n",
      "    self.dbapi_connection = connection = pool._invoke_creator(self)\n",
      "                                         ^^^^^^^^^^^^^^^^^^^^^^^^^^\n",
      "  File \"/usr/local/python/3.12.1/lib/python3.12/site-packages/sqlalchemy/engine/create.py\", line 646, in connect\n",
      "    return dialect.connect(*cargs, **cparams)\n",
      "           ^^^^^^^^^^^^^^^^^^^^^^^^^^^^^^^^^^\n",
      "  File \"/usr/local/python/3.12.1/lib/python3.12/site-packages/sqlalchemy/engine/default.py\", line 622, in connect\n",
      "    return self.loaded_dbapi.connect(*cargs, **cparams)\n",
      "           ^^^^^^^^^^^^^^^^^^^^^^^^^^^^^^^^^^^^^^^^^^^^\n",
      "  File \"/usr/local/python/3.12.1/lib/python3.12/site-packages/psycopg2/__init__.py\", line 122, in connect\n",
      "    conn = _connect(dsn, connection_factory=connection_factory, **kwasync)\n",
      "           ^^^^^^^^^^^^^^^^^^^^^^^^^^^^^^^^^^^^^^^^^^^^^^^^^^^^^^^^^^^^^^^\n",
      "psycopg2.OperationalError: could not connect to server: Connection refused\n",
      "\tIs the server running on host \"localhost\" (::1) and accepting\n",
      "\tTCP/IP connections on port 5432?\n",
      "could not connect to server: Connection refused\n",
      "\tIs the server running on host \"localhost\" (127.0.0.1) and accepting\n",
      "\tTCP/IP connections on port 5432?\n",
      "\n",
      "\n",
      "The above exception was the direct cause of the following exception:\n",
      "\n",
      "Traceback (most recent call last):\n",
      "  File \"/usr/local/python/3.12.1/lib/python3.12/site-packages/sql/magic.py\", line 196, in execute\n",
      "    conn = sql.connection.Connection.set(\n",
      "           ^^^^^^^^^^^^^^^^^^^^^^^^^^^^^^\n",
      "  File \"/usr/local/python/3.12.1/lib/python3.12/site-packages/sql/connection.py\", line 70, in set\n",
      "    cls.current = existing or Connection(descriptor, connect_args, creator)\n",
      "                              ^^^^^^^^^^^^^^^^^^^^^^^^^^^^^^^^^^^^^^^^^^^^^\n",
      "  File \"/usr/local/python/3.12.1/lib/python3.12/site-packages/sql/connection.py\", line 55, in __init__\n",
      "    self.internal_connection = engine.connect()\n",
      "                               ^^^^^^^^^^^^^^^^\n",
      "  File \"/usr/local/python/3.12.1/lib/python3.12/site-packages/sqlalchemy/engine/base.py\", line 3274, in connect\n",
      "    return self._connection_cls(self)\n",
      "           ^^^^^^^^^^^^^^^^^^^^^^^^^^\n",
      "  File \"/usr/local/python/3.12.1/lib/python3.12/site-packages/sqlalchemy/engine/base.py\", line 148, in __init__\n",
      "    Connection._handle_dbapi_exception_noconnection(\n",
      "  File \"/usr/local/python/3.12.1/lib/python3.12/site-packages/sqlalchemy/engine/base.py\", line 2439, in _handle_dbapi_exception_noconnection\n",
      "    raise sqlalchemy_exception.with_traceback(exc_info[2]) from e\n",
      "  File \"/usr/local/python/3.12.1/lib/python3.12/site-packages/sqlalchemy/engine/base.py\", line 146, in __init__\n",
      "    self._dbapi_connection = engine.raw_connection()\n",
      "                             ^^^^^^^^^^^^^^^^^^^^^^^\n",
      "  File \"/usr/local/python/3.12.1/lib/python3.12/site-packages/sqlalchemy/engine/base.py\", line 3298, in raw_connection\n",
      "    return self.pool.connect()\n",
      "           ^^^^^^^^^^^^^^^^^^^\n",
      "  File \"/usr/local/python/3.12.1/lib/python3.12/site-packages/sqlalchemy/pool/base.py\", line 449, in connect\n",
      "    return _ConnectionFairy._checkout(self)\n",
      "           ^^^^^^^^^^^^^^^^^^^^^^^^^^^^^^^^\n",
      "  File \"/usr/local/python/3.12.1/lib/python3.12/site-packages/sqlalchemy/pool/base.py\", line 1263, in _checkout\n",
      "    fairy = _ConnectionRecord.checkout(pool)\n",
      "            ^^^^^^^^^^^^^^^^^^^^^^^^^^^^^^^^\n",
      "  File \"/usr/local/python/3.12.1/lib/python3.12/site-packages/sqlalchemy/pool/base.py\", line 712, in checkout\n",
      "    rec = pool._do_get()\n",
      "          ^^^^^^^^^^^^^^\n",
      "  File \"/usr/local/python/3.12.1/lib/python3.12/site-packages/sqlalchemy/pool/impl.py\", line 179, in _do_get\n",
      "    with util.safe_reraise():\n",
      "  File \"/usr/local/python/3.12.1/lib/python3.12/site-packages/sqlalchemy/util/langhelpers.py\", line 146, in __exit__\n",
      "    raise exc_value.with_traceback(exc_tb)\n",
      "  File \"/usr/local/python/3.12.1/lib/python3.12/site-packages/sqlalchemy/pool/impl.py\", line 177, in _do_get\n",
      "    return self._create_connection()\n",
      "           ^^^^^^^^^^^^^^^^^^^^^^^^^\n",
      "  File \"/usr/local/python/3.12.1/lib/python3.12/site-packages/sqlalchemy/pool/base.py\", line 390, in _create_connection\n",
      "    return _ConnectionRecord(self)\n",
      "           ^^^^^^^^^^^^^^^^^^^^^^^\n",
      "  File \"/usr/local/python/3.12.1/lib/python3.12/site-packages/sqlalchemy/pool/base.py\", line 674, in __init__\n",
      "    self.__connect()\n",
      "  File \"/usr/local/python/3.12.1/lib/python3.12/site-packages/sqlalchemy/pool/base.py\", line 900, in __connect\n",
      "    with util.safe_reraise():\n",
      "  File \"/usr/local/python/3.12.1/lib/python3.12/site-packages/sqlalchemy/util/langhelpers.py\", line 146, in __exit__\n",
      "    raise exc_value.with_traceback(exc_tb)\n",
      "  File \"/usr/local/python/3.12.1/lib/python3.12/site-packages/sqlalchemy/pool/base.py\", line 896, in __connect\n",
      "    self.dbapi_connection = connection = pool._invoke_creator(self)\n",
      "                                         ^^^^^^^^^^^^^^^^^^^^^^^^^^\n",
      "  File \"/usr/local/python/3.12.1/lib/python3.12/site-packages/sqlalchemy/engine/create.py\", line 646, in connect\n",
      "    return dialect.connect(*cargs, **cparams)\n",
      "           ^^^^^^^^^^^^^^^^^^^^^^^^^^^^^^^^^^\n",
      "  File \"/usr/local/python/3.12.1/lib/python3.12/site-packages/sqlalchemy/engine/default.py\", line 622, in connect\n",
      "    return self.loaded_dbapi.connect(*cargs, **cparams)\n",
      "           ^^^^^^^^^^^^^^^^^^^^^^^^^^^^^^^^^^^^^^^^^^^^\n",
      "  File \"/usr/local/python/3.12.1/lib/python3.12/site-packages/psycopg2/__init__.py\", line 122, in connect\n",
      "    conn = _connect(dsn, connection_factory=connection_factory, **kwasync)\n",
      "           ^^^^^^^^^^^^^^^^^^^^^^^^^^^^^^^^^^^^^^^^^^^^^^^^^^^^^^^^^^^^^^^\n",
      "sqlalchemy.exc.OperationalError: (psycopg2.OperationalError) could not connect to server: Connection refused\n",
      "\tIs the server running on host \"localhost\" (::1) and accepting\n",
      "\tTCP/IP connections on port 5432?\n",
      "could not connect to server: Connection refused\n",
      "\tIs the server running on host \"localhost\" (127.0.0.1) and accepting\n",
      "\tTCP/IP connections on port 5432?\n",
      "\n",
      "(Background on this error at: https://sqlalche.me/e/20/e3q8)\n",
      "\n",
      "Connection info needed in SQLAlchemy format, example:\n",
      "               postgresql://username:password@hostname/dbname\n",
      "               or an existing connection: dict_keys([])\n"
     ]
    }
   ],
   "source": [
    "%sql postgresql://admin:root@localhost:5432/finance_data"
   ]
  },
  {
   "cell_type": "markdown",
   "id": "cfe2da64-ec56-4c13-973a-ba7f598331c4",
   "metadata": {},
   "source": [
    "## Create Table in DB and load data "
   ]
  },
  {
   "cell_type": "code",
   "execution_count": 3,
   "id": "6e1b1658-d32b-42b7-ac29-e461108f1cf5",
   "metadata": {},
   "outputs": [
    {
     "name": "stdout",
     "output_type": "stream",
     "text": [
      " * postgresql://admin:***@localhost:5432/finance_data\n",
      "Done.\n",
      "Done.\n",
      "(psycopg2.errors.UndefinedFile) could not open file \"/data/transactions.csv\" for reading: No such file or directory\n",
      "HINT:  COPY FROM instructs the PostgreSQL server process to read a file. You may want a client-side facility such as psql's \\copy.\n",
      "\n",
      "[SQL: -- Copy data from CSV file\n",
      "\n",
      "COPY raw_transactions\n",
      "FROM '/data/transactions.csv' \n",
      "WITH CSV HEADER;]\n",
      "(Background on this error at: https://sqlalche.me/e/20/e3q8)\n"
     ]
    }
   ],
   "source": [
    "%%sql\n",
    "\n",
    "-- Create the transactions table if not exists\n",
    "CREATE TABLE IF NOT EXISTS transactions (\n",
    "    transaction_id VARCHAR PRIMARY KEY,\n",
    "    merchant_id VARCHAR,\n",
    "    transaction_date DATE,\n",
    "    transaction_amount NUMERIC,\n",
    "    currency VARCHAR(10),\n",
    "    payment_method VARCHAR(50),\n",
    "    status VARCHAR(50),\n",
    "    failure_reason VARCHAR(255),\n",
    "    country VARCHAR(100),\n",
    "    customer_id VARCHAR\n",
    ");\n",
    "\n",
    "-- Load data from CSV into a staging table\n",
    "CREATE TEMP TABLE IF NOT EXISTS raw_transactions (\n",
    "    transaction_id VARCHAR,\n",
    "    merchant_id VARCHAR,\n",
    "    transaction_date VARCHAR,\n",
    "    transaction_amount NUMERIC,\n",
    "    currency VARCHAR(10),\n",
    "    payment_method VARCHAR(50),\n",
    "    status VARCHAR(50),\n",
    "    failure_reason VARCHAR(255),\n",
    "    country VARCHAR(100),\n",
    "    customer_id VARCHAR\n",
    ");\n",
    "\n",
    "-- Copy data from CSV file\n",
    "\n",
    "COPY raw_transactions\n",
    "FROM '/data/transactions.csv' \n",
    "WITH CSV HEADER;\n",
    "\n",
    "-- Insert cleaned data into transactions table\n",
    "INSERT INTO transactions\n",
    "SELECT \n",
    "    transaction_id, \n",
    "    merchant_id, \n",
    "    TO_DATE(transaction_date, 'YYYY-MM-DD') AS transaction_date, \n",
    "    transaction_amount, \n",
    "    currency, \n",
    "    payment_method, \n",
    "    status, \n",
    "    COALESCE(failure_reason, 'N/A') AS failure_reason, \n",
    "    country, \n",
    "    customer_id\n",
    "FROM raw_transactions;\n",
    "\n",
    "-- Drop the temporary staging table\n",
    "DROP TABLE raw_transactions;"
   ]
  },
  {
   "cell_type": "code",
   "execution_count": null,
   "id": "496d4b14-4ea0-4f81-a50b-bfb5bec0299a",
   "metadata": {},
   "outputs": [],
   "source": [
    "%%sql\n",
    "\n",
    "INSERT INTO transactions\n",
    "SELECT \n",
    "    transaction_id, \n",
    "    merchant_id, \n",
    "    TO_DATE(transaction_date, 'YYYY-MM-DD') AS transaction_date, \n",
    "    transaction_amount, \n",
    "    currency, \n",
    "    payment_method, \n",
    "    status, \n",
    "    COALESCE(failure_reason, 'N/A') AS failure_reason, \n",
    "    country, \n",
    "    customer_id\n",
    "FROM raw_transactions;"
   ]
  }
 ],
 "metadata": {
  "kernelspec": {
   "display_name": "Python 3 (ipykernel)",
   "language": "python",
   "name": "python3"
  },
  "language_info": {
   "codemirror_mode": {
    "name": "ipython",
    "version": 3
   },
   "file_extension": ".py",
   "mimetype": "text/x-python",
   "name": "python",
   "nbconvert_exporter": "python",
   "pygments_lexer": "ipython3",
   "version": "3.12.1"
  }
 },
 "nbformat": 4,
 "nbformat_minor": 5
}
